Workbook

Sheet Akun
A1: ID Anggota | B1: Email | C1: PIN | D1: Status PIN | E1: Role | F1: Status Akun
A2: DBP00000000 | B2: halo.ikadbp@gmail.com | C2: 111111 | D2: Default | E2: Anggota | F2: Aktif
A3: =IFERROR(__xludf.DUMMYFUNCTION("QUERY(Database!A3:G2003,""Select A,G"",)"),"DBP01000001") -> DBP01000001 | B3: =IFERROR(__xludf.DUMMYFUNCTION("""COMPUTED_VALUE"""),"akbar.lawyer85@gmail.com") -> akbar.lawyer85@gmail.com | C3: 260185 | D3: Changed | E3: Anggota | F3: Aktif
A4: =IFERROR(__xludf.DUMMYFUNCTION("""COMPUTED_VALUE"""),"DBP01000002") -> DBP01000002 | B4: =IFERROR(__xludf.DUMMYFUNCTION("""COMPUTED_VALUE"""),"avgoenadi@gmail.com") -> avgoenadi@gmail.com | C4: 112233 | D4: Changed | E4: Anggota | F4: Aktif
A5: =IFERROR(__xludf.DUMMYFUNCTION("""COMPUTED_VALUE"""),"DBP01000003") -> DBP01000003 | B5: =IFERROR(__xludf.DUMMYFUNCTION("""COMPUTED_VALUE"""),"gema.kusumaputri@gmail.com") -> gema.kusumaputri@gmail.com | C5: 123123 | D5: Default | E5: Anggota | F5: Aktif
A6: =IFERROR(__xludf.DUMMYFUNCTION("""COMPUTED_VALUE"""),"DBP01000004") -> DBP01000004 | B6: =IFERROR(__xludf.DUMMYFUNCTION("""COMPUTED_VALUE"""),"putuagnia@gmail.com") -> putuagnia@gmail.com | C6: 123123 | D6: Default | E6: Anggota | F6: Aktif
A7: =IFERROR(__xludf.DUMMYFUNCTION("""COMPUTED_VALUE"""),"DBP01000005") -> DBP01000005 | B7: =IFERROR(__xludf.DUMMYFUNCTION("""COMPUTED_VALUE"""),"dante.darmawangsa@upi.edu") -> dante.darmawangsa@upi.edu | C7: 123123 | D7: Default | E7: Anggota | F7: Aktif
A8: =IFERROR(__xludf.DUMMYFUNCTION("""COMPUTED_VALUE"""),"DBP01000006") -> DBP01000006 | B8: =IFERROR(__xludf.DUMMYFUNCTION("""COMPUTED_VALUE"""),"ratri.mustikaning.h@gmail.com") -> ratri.mustikaning.h@gmail.com | C8: 123123 | D8: Default | E8: Anggota | F8: Aktif
A9: =IFERROR(__xludf.DUMMYFUNCTION("""COMPUTED_VALUE"""),"DBP01000007") -> DBP01000007 | B9: =IFERROR(__xludf.DUMMYFUNCTION("""COMPUTED_VALUE"""),"puti.kemala.tanjung@gmail.com") -> puti.kemala.tanjung@gmail.com | C9: 123123 | D9: Default | E9: Anggota | F9: Aktif
A10: =IFERROR(__xludf.DUMMYFUNCTION("""COMPUTED_VALUE"""),"DBP01000008") -> DBP01000008 | B10: =IFERROR(__xludf.DUMMYFUNCTION("""COMPUTED_VALUE"""),"roroajengtaufik@gmail.com") -> roroajengtaufik@gmail.com | C10: 123123 | D10: Default | E10: Anggota | F10: Aktif
A11: =IFERROR(__xludf.DUMMYFUNCTION("""COMPUTED_VALUE"""),"DBP01000009") -> DBP01000009 | B11: =IFERROR(__xludf.DUMMYFUNCTION("""COMPUTED_VALUE"""),"wayqodratulloh@gmail.com") -> wayqodratulloh@gmail.com | C11: 123123 | D11: Default | E11: Anggota | F11: Aktif
A12: =IFERROR(__xludf.DUMMYFUNCTION("""COMPUTED_VALUE"""),"DBP01000010") -> DBP01000010 | B12: =IFERROR(__xludf.DUMMYFUNCTION("""COMPUTED_VALUE"""),"gp.handoko15@gmail.com") -> gp.handoko15@gmail.com | C12: 123123 | D12: Default | E12: Anggota | F12: Aktif
A13: =IFERROR(__xludf.DUMMYFUNCTION("""COMPUTED_VALUE"""),"DBP01000011") -> DBP01000011 | B13: =IFERROR(__xludf.DUMMYFUNCTION("""COMPUTED_VALUE"""),"doddyfirman@yahoo.com") -> doddyfirman@yahoo.com | C13: 123123 | D13: Default | E13: Anggota | F13: Aktif
A14: =IFERROR(__xludf.DUMMYFUNCTION("""COMPUTED_VALUE"""),"DBP01000012") -> DBP01000012 | B14: =IFERROR(__xludf.DUMMYFUNCTION("""COMPUTED_VALUE"""),"hawitguritno@gmail.com") -> hawitguritno@gmail.com | C14: 123123 | D14: Default | E14: Anggota | F14: Aktif
A15: =IFERROR(__xludf.DUMMYFUNCTION("""COMPUTED_VALUE"""),"DBP01000013") -> DBP01000013 | B15: =IFERROR(__xludf.DUMMYFUNCTION("""COMPUTED_VALUE"""),"malaekayanti@gmail.com") -> malaekayanti@gmail.com | C15: 123123 | D15: Default | E15: Anggota | F15: Aktif
A16: =IFERROR(__xludf.DUMMYFUNCTION("""COMPUTED_VALUE"""),"DBP01000014") -> DBP01000014 | B16: =IFERROR(__xludf.DUMMYFUNCTION("""COMPUTED_VALUE"""),"rizkiarisy@gmail.com") -> rizkiarisy@gmail.com | C16: 123123 | D16: Default | E16: Anggota | F16: Aktif
A17: =IFERROR(__xludf.DUMMYFUNCTION("""COMPUTED_VALUE"""),"DBP01000015") -> DBP01000015 | B17: =IFERROR(__xludf.DUMMYFUNCTION("""COMPUTED_VALUE"""),"fazia.febriany@gmail.com") -> fazia.febriany@gmail.com | C17: 123123 | D17: Default | E17: Anggota | F17: Aktif
A18: =IFERROR(__xludf.DUMMYFUNCTION("""COMPUTED_VALUE"""),"DBP01000016") -> DBP01000016 | B18: =IFERROR(__xludf.DUMMYFUNCTION("""COMPUTED_VALUE"""),"wijayajilan@gmail.com") -> wijayajilan@gmail.com | C18: 123123 | D18: Default | E18: Anggota | F18: Aktif
A19: =IFERROR(__xludf.DUMMYFUNCTION("""COMPUTED_VALUE"""),"DBP01000017") -> DBP01000017 | B19: =IFERROR(__xludf.DUMMYFUNCTION("""COMPUTED_VALUE"""),"nurrohmanazis1992@gmail.com") -> nurrohmanazis1992@gmail.com | C19: 123123 | D19: Default | E19: Anggota | F19: Aktif
A20: =IFERROR(__xludf.DUMMYFUNCTION("""COMPUTED_VALUE"""),"DBP01000018") -> DBP01000018 | C20: 123123 | D20: Default | E20: Anggota | F20: Aktif
A21: =IFERROR(__xludf.DUMMYFUNCTION("""COMPUTED_VALUE"""),"DBP01000019") -> DBP01000019 | B21: =IFERROR(__xludf.DUMMYFUNCTION("""COMPUTED_VALUE"""),"nicho.tarigan@gmail.com") -> nicho.tarigan@gmail.com | C21: 123123 | D21: Default | E21: Anggota | F21: Aktif
A22: =IFERROR(__xludf.DUMMYFUNCTION("""COMPUTED_VALUE"""),"DBP01000020") -> DBP01000020 | B22: =IFERROR(__xludf.DUMMYFUNCTION("""COMPUTED_VALUE"""),"Ogyfabrio@gmail.com") -> Ogyfabrio@gmail.com | C22: 123123 | D22: Default | E22: Anggota | F22: Aktif
A23: =IFERROR(__xludf.DUMMYFUNCTION("""COMPUTED_VALUE"""),"DBP01000021") -> DBP01000021 | B23: =IFERROR(__xludf.DUMMYFUNCTION("""COMPUTED_VALUE"""),"suhandies@gmail.com") -> suhandies@gmail.com | C23: 123123 | D23: Default | E23: Anggota | F23: Aktif
A24: =IFERROR(__xludf.DUMMYFUNCTION("""COMPUTED_VALUE"""),"DBP01000022") -> DBP01000022 | B24: =IFERROR(__xludf.DUMMYFUNCTION("""COMPUTED_VALUE"""),"riyadhi.atha@gmail.com") -> riyadhi.atha@gmail.com | C24: 123123 | D24: Default | E24: Anggota | F24: Aktif
A25: =IFERROR(__xludf.DUMMYFUNCTION("""COMPUTED_VALUE"""),"DBP01000023") -> DBP01000023 | B25: =IFERROR(__xludf.DUMMYFUNCTION("""COMPUTED_VALUE"""),"Marthanitaflorentinas@gmail.com") -> Marthanitaflorentinas@gmail.com | C25: 123123 | D25: Default | E25: Anggota | F25: Aktif
A26: =IFERROR(__xludf.DUMMYFUNCTION("""COMPUTED_VALUE"""),"DBP01000024") -> DBP01000024 | B26: =IFERROR(__xludf.DUMMYFUNCTION("""COMPUTED_VALUE"""),"ferdinand.hiu@gmail.com") -> ferdinand.hiu@gmail.com | C26: 123123 | D26: Default | E26: Anggota | F26: Aktif
A27: =IFERROR(__xludf.DUMMYFUNCTION("""COMPUTED_VALUE"""),"DBP01000025") -> DBP01000025 | B27: =IFERROR(__xludf.DUMMYFUNCTION("""COMPUTED_VALUE"""),"sagitas@xlfutureleaders.com") -> sagitas@xlfutureleaders.com | C27: 123123 | D27: Default | E27: Anggota | F27: Aktif
A28: =IFERROR(__xludf.DUMMYFUNCTION("""COMPUTED_VALUE"""),"DBP01000026") -> DBP01000026 | B28: =IFERROR(__xludf.DUMMYFUNCTION("""COMPUTED_VALUE"""),"herozh94@gmail.com") -> herozh94@gmail.com | C28: 123123 | D28: Default | E28: Anggota | F28: Aktif
A29: =IFERROR(__xludf.DUMMYFUNCTION("""COMPUTED_VALUE"""),"DBP01000027") -> DBP01000027 | B29: =IFERROR(__xludf.DUMMYFUNCTION("""COMPUTED_VALUE"""),"Fjrhdy11@gmail.com") -> Fjrhdy11@gmail.com | C29: 123123 | D29: Default | E29: Anggota | F29: Aktif
A30: =IFERROR(__xludf.DUMMYFUNCTION("""COMPUTED_VALUE"""),"DBP01000028") -> DBP01000028 | B30: =IFERROR(__xludf.DUMMYFUNCTION("""COMPUTED_VALUE"""),"khasanm86@gmail.com") -> khasanm86@gmail.com | C30: 123123 | D30: Default | E30: Anggota | F30: Aktif
A31: =IFERROR(__xludf.DUMMYFUNCTION("""COMPUTED_VALUE"""),"DBP01000029") -> DBP01000029 | B31: =IFERROR(__xludf.DUMMYFUNCTION("""COMPUTED_VALUE"""),"ilham.pbd@gmail.com") -> ilham.pbd@gmail.com | C31: 30419 | D31: Changed | E31: Anggota | F31: Aktif
A32: =IFERROR(__xludf.DUMMYFUNCTION("""COMPUTED_VALUE"""),"DBP01000030") -> DBP01000030 | B32: =IFERROR(__xludf.DUMMYFUNCTION("""COMPUTED_VALUE"""),"shafi.faris33@gmail.com") -> shafi.faris33@gmail.com | C32: 123123 | D32: Default | E32: Anggota | F32: Aktif
A33: =IFERROR(__xludf.DUMMYFUNCTION("""COMPUTED_VALUE"""),"DBP01000031") -> DBP01000031 | B33: =IFERROR(__xludf.DUMMYFUNCTION("""COMPUTED_VALUE"""),"Hapinksihanti89@gmail.com ") -> Hapinksihanti89@gmail.com | C33: 123123 | D33: Default | E33: Anggota | F33: Aktif
A34: =IFERROR(__xludf.DUMMYFUNCTION("""COMPUTED_VALUE"""),"DBP01000032") -> DBP01000032 | B34: =IFERROR(__xludf.DUMMYFUNCTION("""COMPUTED_VALUE"""),"didopranata@gmail.com") -> didopranata@gmail.com | C34: 123123 | D34: Default | E34: Anggota | F34: Aktif
A35: =IFERROR(__xludf.DUMMYFUNCTION("""COMPUTED_VALUE"""),"DBP01000033") -> DBP01000033 | B35: =IFERROR(__xludf.DUMMYFUNCTION("""COMPUTED_VALUE"""),"putununiek89@unhi.ac.id") -> putununiek89@unhi.ac.id | C35: 123123 | D35: Default | E35: Anggota | F35: Aktif
A36: =IFERROR(__xludf.DUMMYFUNCTION("""COMPUTED_VALUE"""),"DBP01000034") -> DBP01000034 | B36: =IFERROR(__xludf.DUMMYFUNCTION("""COMPUTED_VALUE"""),"neserike@gmail.com") -> neserike@gmail.com | C36: 123123 | D36: Default | E36: Anggota | F36: Aktif
A37: =IFERROR(__xludf.DUMMYFUNCTION("""COMPUTED_VALUE"""),"DBP01000035") -> DBP01000035 | B37: =IFERROR(__xludf.DUMMYFUNCTION("""COMPUTED_VALUE"""),"yudith.tm@gmail.com") -> yudith.tm@gmail.com | C37: 123123 | D37: Default | E37: Anggota | F37: Aktif
A38: =IFERROR(__xludf.DUMMYFUNCTION("""COMPUTED_VALUE"""),"DBP01000036") -> DBP01000036 | C38: 123123 | D38: Default | E38: Anggota | F38: Aktif
A39: =IFERROR(__xludf.DUMMYFUNCTION("""COMPUTED_VALUE"""),"DBP01000037") -> DBP01000037 | B39: =IFERROR(__xludf.DUMMYFUNCTION("""COMPUTED_VALUE"""),"deidranataliet@gmail.com") -> deidranataliet@gmail.com | C39: 123123 | D39: Default | E39: Anggota | F39: Aktif
A40: =IFERROR(__xludf.DUMMYFUNCTION("""COMPUTED_VALUE"""),"DBP01000038") -> DBP01000038 | B40: =IFERROR(__xludf.DUMMYFUNCTION("""COMPUTED_VALUE"""),"dianboer@gmail.com") -> dianboer@gmail.com | C40: 123123 | D40: Default | E40: Anggota | F40: Aktif
...

Sheet Database
A1: ID Anggota | B1: Nama Lengkap | C1: Jenis Kelamin | D1: Tempat Lahir | E1: Tanggal Lahir | F1: Nomor Whatsapp | G1: Email | H1: Angkatan | I1: Pendidikan | J1: Universitas | K1: Fakultas | L1: Jurusan | M1: Negara Domisili | N1: Provinsi Domisili | O1: Kota Domisili | P1: Foto | Q1: LinkedIn | R1: Sektor Industri | S1: Jenis Pekerjaan | T1: Jabatan | U1: Nama Instansi | V1: Hobi | W1: Minat | X1: Komunitas Lain | Y1: Memiliki Usaha | Z1: Nama Usaha | AA1: Deskripsi Usaha | AB1: Bidang Usaha | AC1: Jabatan dalam Usaha | AD1: Lokasi Usaha | AE1: Persetujuan Data
A2: DBP00000000 | B2: HALO IKADBP | F2: 1234567890 | G2: halo.ikadbp@gmail.com | N2: , | P2: https://drive.google.com/file/d/1N9Bc4A9fu-dGoJXVf5LIR2gqW5eR1E_v/view?usp=drivesdk | Q2: aa | Y2: TIDAK
A3: DBP01000001 | B3: AKBAR HIDAYATULLAH | C3: LAKI-LAKI | E3: 31366 | G3: akbar.lawyer85@gmail.com | H3: 21 (2005/2006) | I3: S1 | J3: UNIVERSITAS TANJUNGPURA | K3: HUKUM | L3: ILMU HUKUM | M3: INDONESIA | N3: DKI JAKARTA, | O3: JAKARTA UTARA | P3: https://drive.google.com/open?id=1dZLLXnEqh1bvBprkkDfByp6VTdqn0zRG | Q3: https://www.linkedin.com/in/akbar-hidayatullah-926307a0?utm_source=share&utm_campaign=share_via&utm_content=profile&utm_medium=android_app | R3: HUKUM / LEGAL | S3: KURATOR | Y3: YA | AB3: HUKUM / JASA HUKUM
A4: DBP01000002 | B4: ANGGI VALENTINATA GOENADI | C4: LAKI-LAKI | E4: 32502 | G4: avgoenadi@gmail.com | P4: https://drive.google.com/open?id=18YkV4XqMuh3BHoCdIGzb0pWVeVE9wMGl
A5: DBP01000003 | B5: GEMA KUSUMAPUTRI | C5: PEREMPUAN | E5: 32891 | G5: gema.kusumaputri@gmail.com | P5: https://drive.google.com/open?id=1owUHoELFCvxo6tpP0WKM2G6U9ON9ywES
A6: DBP01000004 | B6: PUTU AGNIA | C6: PEREMPUAN | E6: 32697 | G6: putuagnia@gmail.com | P6: https://drive.google.com/open?id=1SyqgjYPKGOI33_ntdaxfSIL9YZUqqUUV
A7: DBP01000005 | B7: DANTE DARMAWANGSA | C7: LAKI-LAKI | E7: 30630 | G7: dante.darmawangsa@upi.edu
A8: DBP01000006 | B8: RATRI MUSTIKANING HANDOKO | C8: PEREMPUAN | E8: 31703 | G8: ratri.mustikaning.h@gmail.com | P8: https://drive.google.com/open?id=1UnoMc0RoeaTRuOzdL9TjzO-BMJgEHexF
A9: DBP01000007 | B9: PUTI KEMALA TANJUNG | C9: PEREMPUAN | E9: 32629 | G9: puti.kemala.tanjung@gmail.com
A10: DBP01000008 | B10: RORO AJENG SEKAR ARUM | C10: PEREMPUAN | E10: 33480 | G10: roroajengtaufik@gmail.com | P10: https://drive.google.com/open?id=1jyXayGvxEtA0vKip7ooJbDRBfZcSj9CE
A11: DBP01000009 | B11: WAWAY QODRATULLOH S | C11: LAKI-LAKI | E11: 30660 | G11: wayqodratulloh@gmail.com | P11: https://drive.google.com/open?id=1C2c3r1oBScuK8dK0AIsCP-Iyy1f5PGlO
A12: DBP01000010 | B12: GALIH PURWO HANDOKO | C12: LAKI-LAKI | E12: 31062 | G12: gp.handoko15@gmail.com | P12: https://drive.google.com/open?id=1AY4BtwQrHuDoyUH7iE1e3rQj_xCUj9hj
A13: DBP01000011 | B13: DODDY FIRMAN RAHMADI | C13: LAKI-LAKI | E13: 32202 | G13: doddyfirman@yahoo.com | P13: https://drive.google.com/open?id=12qS9yRfEvTGnMBciqxtMn5ztACQ0uWpU
A14: DBP01000012 | B14: HAWIT GURITNO | C14: LAKI-LAKI | E14: 32273 | G14: hawitguritno@gmail.com | P14: https://drive.google.com/open?id=1WLCrou2ykBlWIpVVKZ0chh9px9s6EYFC
A15: DBP01000013 | B15: MALA EKAYANTI | C15: PEREMPUAN | E15: 30976 | G15: malaekayanti@gmail.com | P15: https://drive.google.com/open?id=1_B8Szrryj4v2gosmG81cqsVjW95vEFyM
A16: DBP01000014 | B16: RIZKI ARIS YUNIANTO | C16: LAKI-LAKI | D16: MOJOKERTO | E16: 33042 | F16: 6285646452425 | G16: rizkiarisy@gmail.com | N16: , | P16: https://drive.google.com/file/d/1-s30EMjp_mlzrDWAzVug1IW32CamjLGZ/view?usp=drivesdk
A17: DBP01000015 | B17: FAZIA FEBRIANY | C17: PEREMPUAN | E17: 32551 | G17: fazia.febriany@gmail.com | P17: https://drive.google.com/open?id=1sWuKnUEnUtClk3zP06OYMsfSf34PV6Z9
A18: DBP01000016 | B18: JIILAN RANA WIJAYA | C18: LAKI-LAKI | E18: 34075 | G18: wijayajilan@gmail.com | P18: https://drive.google.com/open?id=16DNpFTZVMsuzW4mJdpZcXkNDRPEw81QV
A19: DBP01000017 | B19: NUR ROHMAN AZIS | C19: LAKI-LAKI | E19: 33665 | G19: nurrohmanazis1992@gmail.com | P19: https://drive.google.com/open?id=18s-qjy_Z49fkw7qPNTGcsw7ZyewHF5dK
A20: DBP01000018 | B20: DEDY HERIANSYAH | C20: LAKI-LAKI | P20: https://drive.google.com/open?id=1n5DJkjSBeOJIocVncNJoZDTqvsA4_yne
A21: DBP01000019 | B21: NICHO ADHI PUTRA TARIGAN | C21: LAKI-LAKI | E21: 33664 | G21: nicho.tarigan@gmail.com | P21: https://drive.google.com/open?id=1UIexVBPr4seYDJh4dzSeECNwuBe1HZ3X
A22: DBP01000020 | B22: OGY FABRIO MANDALA | C22: LAKI-LAKI | E22: 33750 | G22: Ogyfabrio@gmail.com | P22: https://drive.google.com/open?id=19gnLGoIgRchUheLlYobOkbJW0UQkwIwQ
A23: DBP01000021 | B23: SUHANDI | C23: LAKI-LAKI | E23: 32375 | G23: suhandies@gmail.com | P23: https://drive.google.com/open?id=1c2WL_PljoOhZTOeycmfKAuflpd8_zxEt
A24: DBP01000022 | B24: ATHA FITRAH RIYADHI | C24: LAKI-LAKI | E24: 35364 | G24: riyadhi.atha@gmail.com | P24: https://drive.google.com/open?id=1IJbfMnb1IfBKtdOUXm8T5gKJZZZa-icm
A25: DBP01000023 | B25: MARTHA NITA FLORENTINA S | C25: PEREMPUAN | E25: 32222 | G25: Marthanitaflorentinas@gmail.com | P25: https://drive.google.com/open?id=1BGvxMK--L8hYfZ8OnhWQQarfwA16HH0f
A26: DBP01000024 | B26: FERDINAND HIDAYAT | C26: LAKI-LAKI | E26: 32906 | G26: ferdinand.hiu@gmail.com | P26: https://drive.google.com/open?id=1c7YCvR6j6E1fH6c4RXKHpqk5AhGWylWi
A27: DBP01000025 | B27: SARITA GILLYAN KARTIKASARI | C27: PEREMPUAN | E27: 33575 | G27: sagitas@xlfutureleaders.com | P27: https://drive.google.com/open?id=16jdWbfRCCjJDI5heJhc9oPvwhU9xN7vM
A28: DBP01000026 | B28: RAHMANDHIKA FIRDAUZHA HARY HERNANDHA | C28: LAKI-LAKI | E28: 34402 | G28: herozh94@gmail.com | P28: https://drive.google.com/open?id=1Iudu6kfE3lR_VoRE8ZPam_kTrC3Sl5Tq
A29: DBP01000027 | B29: FAJAR HUDOYO | C29: LAKI-LAKI | E29: 36073 | G29: Fjrhdy11@gmail.com | P29: https://drive.google.com/open?id=1RHjjAMcOMflzpwaucX1ttgcug_HNb5_z
A30: DBP01000028 | B30: MOHAMMAD KHASAN | C30: LAKI-LAKI | E30: 31576 | G30: khasanm86@gmail.com | P30: https://drive.google.com/open?id=1X-tEB_zvK7eOZLrbf3gYwu1UjJutcJAV
A31: DBP01000029 | B31: ILHAM ARIFIN PAMBUDI | C31: LAKI-LAKI | E31: 35951 | G31: ilham.pbd@gmail.com | P31: https://drive.google.com/open?id=1J35rD2hwuXLvuUd9odBiSMmtSDRHJvHZ
A32: DBP01000030 | B32: FARIS SHAFI SULISTYA | C32: LAKI-LAKI | E32: 32826 | G32: shafi.faris33@gmail.com | P32: https://drive.google.com/open?id=17TbrGNPS4PsdMFI9EYyZhLsDaQ9MX3zX
A33: DBP01000031 | B33: HAPPY DYAH SIHANTI | C33: PEREMPUAN | E33: 32600 | F33: 08113660999 | G33: Hapinksihanti89@gmail.com | H33: 25 (2009/2010) | I33: S1 | J33: UNIVERSITAS MERDEKA MALANG | K33: PSIKOLOGI | L33: PSIKOLOGI | M33: INDONESIA | N33: JAWA TIMUR, | O33: MALANG | P33: https://drive.google.com/file/d/1-FDdPQCnFAYOhJX2KqC6cYcUOxZwvzRD/view?usp=drivesdk | Q33: Happy dyah sihanti | R33: KEUANGAN / PERBANKAN / ASURANSI | S33: MARKETING / SALES / PR | T33: PREMIER BANKING MANAGER | U33: PT BANK OCBC | V33: MENYANYI | Y33: TIDAK
A34: DBP01000032 | B34: JANISATYA DIDO | C34: LAKI-LAKI | G34: didopranata@gmail.com
A35: DBP01000033 | B35: PUTU NUNIEK HUTNALEONTINA | C35: PEREMPUAN | E35: 32597 | G35: putununiek89@unhi.ac.id | P35: https://drive.google.com/open?id=19_oyIC75DRXnB5wCXBEXldXyeWoYJjy0
A36: DBP01000034 | B36: NESER IKE CAHYANINGRUM | C36: PEREMPUAN | E36: 32762 | G36: neserike@gmail.com | P36: https://drive.google.com/open?id=1QaAUYJapy1sVfPL-A55D8blTBnLkZo8P
A37: DBP01000035 | B37: YUDITH SANDRI RONDONUWU | C37: PEREMPUAN | E37: 31247 | G37: yudith.tm@gmail.com | P37: https://drive.google.com/open?id=1h8L2hMJfsjrLbya2H3a1Rb0QFZ22YI1u
A38: DBP01000036 | B38: ZULQADRI SUAIB | C38: LAKI-LAKI
A39: DBP01000037 | B39: DEIDRA NATALIE TOMASOA | C39: PEREMPUAN | E39: 35058 | G39: deidranataliet@gmail.com | P39: https://drive.google.com/open?id=1jpOPghzMWRoumgKehyNWYB-ubikpvZCr
A40: DBP01000038 | B40: GALIO RUDOLFO DIAN BURDAMES | C40: LAKI-LAKI | E40: 33548 | G40: dianboer@gmail.com | P40: https://drive.google.com/open?id=190zi2YIW7GxUB5zmCopJnMZRkPWHEzNv
...

Sheet TempPendaftar
A1: Timestamp | B1: Status | C1: Nama Lengkap | D1: Jenis Kelamin | E1: Tempat Lahir | F1: Tanggal Lahir | G1: Nomor Whatsapp | H1: Email | I1: PIN | J1: Angkatan | K1: Pendidikan | L1: Universitas | M1: Fakultas | N1: Jurusan | O1: Negara Domisili | P1: Provinsi Domisili | Q1: Kota Domisili | R1: Foto | S1: LinkedIn | T1: Sektor Industri | U1: Jenis Pekerjaan | V1: Jabatan | W1: Nama Instansi | X1: Hobi | Y1: Minat | Z1: Komunitas Lain | AA1: Memiliki Usaha | AB1: Nama Usaha | AC1: Deskripsi Usaha | AD1: Bidang Usaha | AE1: Jabatan dalam Usaha | AF1: Lokasi Usaha | AG1: Persetujuan Data
A2: 45990.87 | B2: Pending | C2: IKATAN ALUMNI DJARUM BEASISWA PLUS | D2: - | E2: JAKARTA | F2: 2025-11-29 | G2: 08123456789 | H2: halo.ikadbp@gmail.co.id | I2: 123456 | J2: 30 (2014/2015) | K2: S1 | L2: UNIVERSITAS BINA NUSANTARA | M2: TEKNIK | N2: TEKNIK INFORMATIKA | O2: INDONESIA | P2: DKI JAKARTA | Q2: TANGERANG | R2: https://drive.google.com/file/d/1bbEjPePIqr7Wjazm0exVx3lZ5FgSzD70/view?usp=drivesdk | T2: LAINNYA | U2: EDUKASI (DOSEN / GURU / PENELITI) | V2: DOSEN | W2: UNIVERSITAS BINA NUSANTARA | AA2: Ya | AD2: PERTANIAN DAN PETERNAKAN | AG2: on

Sheet Agenda
A1: ID Agenda | B1: Judul Kegiatan | C1: Tanggal | D1: Deskripsi Singkat | E1: Lokasi | F1: Status
A2: KT001 | B2: Pemilu Ketua Umum | C2: 45912 | D2: Pemilihan Ketua Umum | E2: Zoom | F2: Tutup

Sheet DataPartisipan
A1: Timestamp | B1: ID Agenda | C1: Judul Kegiatan | D1: ID Anggota | E1: Anggota | F1: Email | G1: No WA
A2: 45999.794 | B2: KT001 | C2: Pemilu Ketua Umum | D2: DBP01000040 | E2: RICO HALIM | F2: ricohalim46@gmail.com | G2: 6282360853214

Sheet Login Log
A1: Timestamp | B1: Email | C1: ID Anggota | D1: Status | E1: Deskripsi
A2: 45990.728 | B2: ricohalim46@gmail.com | C2: DBP01000040 | D2: Sukses | E2: Login OK
A3: 45990.73 | B3: rizkiarisy@gmail.com | C3: DBP01000014 | D3: Gagal | E3: Wrong PIN
A4: 45990.73 | B4: rizkiarisy@gmail.com | C4: DBP01000014 | D4: Sukses | E4: Login OK
A5: 45990.731 | B5: ricohalim46@gmail.com | C5: DBP01000040 | D5: Sukses | E5: Login OK
A6: 45990.739 | B6: ricohalim46@gmail.com | C6: DBP01000040 | D6: Sukses | E6: Login OK
A7: 45990.739 | B7: dudih.sutrisman@yahoo.co.id | C7: DBP01000052 | D7: Gagal | E7: Wrong PIN
A8: 45990.74 | B8: dudih.sutrisman@yahoo.co.id | C8: DBP01000052 | D8: Sukses | E8: Login OK
A9: 45990.741 | B9: ricohalim46@gmail.com | C9: DBP01000040 | D9: Sukses | E9: Login OK
A10: 45990.741 | B10: faizaldikky@gmail.com | C10: DBP01000046 | D10: Sukses | E10: Login OK
A11: 45990.752 | B11: faizaldikky@gmail.com | C11: DBP01000046 | D11: Sukses | E11: Login OK
A12: 45990.753 | B12: ricohalim46@gmail.com | C12: DBP01000040 | D12: Sukses | E12: Login OK
A13: 45990.757 | B13: faizaldikky@gmail.com | C13: DBP01000046 | D13: Sukses | E13: Login OK
... A84: 46008.768 | B84: budidennn@gmail.com | C84: DBP01000078 | D84: Sukses | E84: Login OK
A85: 46008.768 | B85: ilham.pbd@gmail.com | D85: Gagal | E85: Email not found
A86: 46008.768 | B86: hapinksihanti89@gmail.com | C86: DBP01000031 | D86: Gagal | E86: Wrong PIN
A87: 46008.768 | B87: ilham.pbd@gmail.com | C87: DBP01000029 | D87: Sukses | E87: Login OK
A88: 46008.768 | B88: rikarahmayuni08@gmail.com | C88: DBP01000048 | D88: Sukses | E88: Login OK
A89: 46008.77 | B89: akbar.lawyer85@gmail.com | C89: DBP01000001 | D89: Sukses | E89: Login OK
A90: 46008.77 | B90: rikarahmayuni08@gmail.com | C90: DBP01000048 | D90: Sukses | E90: Login OK
A91: 46008.771 | B91: neserike@gmail.com | C91: DBP01000034 | D91: Sukses | E91: Login OK
A92: 46008.771 | B92: akbar.lawyer85@gmail.com | C92: DBP01000001 | D92: Sukses | E92: Login OK
A93: 46008.772 | B93: suparmanwakidi.s.ak@gmail.com | C93: DBP01000076 | D93: Sukses | E93: Login OK
A94: 46008.772 | B94: hapinksihanti89@gmail.com | C94: DBP01000031 | D94: Sukses | E94: Login OK
A95: 46008.776 | B95: ikarezvaniaprita@gmail.com | C95: DBP01000062 | D95: Sukses | E95: Login OK

Sheet Ref
A1: Jenis Kelamin | B1: Angkatan | C1: Pendidikan | D1: Negara | E1: Provinsi | F1: Universitas | G1: Fakultas | H1: Jenis Pekerjaan | I1: Bidang Usaha | J1: Memiliki Usaha | K1: Sektor Industri
A2: LAKI-LAKI | B2: 18 (2002/2003) | C2: D4 | D2: INDONESIA | E2: ACEH | F2: IAIN KUDUS | G2: HUKUM | H2: AKUNTANSI / KEUANGAN / PAJAK | I2: MAKANAN DAN MINUMAN | J2: Ya | K2: PEMERINTAHAN / BUMN
A3: PEREMPUAN | B3: 19 (2003/2004) | C3: S1 | D3: AFGANISTAN | E3: BALI | F3: INSTITUT KESENIAN JAKARTA | G3: ILMU SOSIAL DAN ILMU POLITIK | H3: ADMINISTRASI / SEKRETARIS | I3: KREATIF DAN SENI | J3: Tidak | K3: PENDIDIKAN / AKADEMISI
B4: 20 (2004/2005) | C4: S2 | D4: AFRIKA SELATAN | E4: BANTEN | F4: INSTITUT PERTANIAN BOGOR | H4: ARSITEK / DESAIN INTERIOR | I4: PENDIDIKAN DAN PELATIHAN | K4: KESEHATAN / MEDIS
B5: 21 (2005/2006) | D5: ALBANIA | E5: BENGKULU | F5: INSTITUT SENI INDONESIA YOGYAKARTA | H5: DESAIN GRAFIS / MULTIMEDIA / KREATIF | I5: MODE DAN PAKAIAN | K5: TEKNOLOGI / IT / STARTUP
B6: 22 (2006/2007) | D6: ALJAZAIR | E6: DI YOGYAKARTA | F6: INSTITUT TEKNOLOGI BANDUNG | H6: DOKTER / PERAWAT / TENAGA MEDIS | I6: PERDAGANGAN DAN DISTRIBUSI | K6: KEUANGAN / PERBANKAN / ASURANSI
B7: 23 (2007/2008) | D7: AMERIKA SERIKAT | E7: DKI JAKARTA | F7: INSTITUT TEKNOLOGI HARAPAN BANGSA | H7: EDUKASI (DOSEN / GURU / PENELITI) | I7: TEKNOLOGI DAN DIGITAL | K7: KONSTRUKSI / PROPERTI
B8: 24 (2008/2009) | D8: ANDORRA | E8: GORONTALO | F8: INSTITUT TEKNOLOGI KALIMANTAN | H8: ENGINEERING / TEKNIK (SIPIL, MESIN, ELEKTRO, DLL) | I8: KONSTRUKSI DAN PROPERTI | K8: ENERGI / MIGAS / PERTAMBANGAN
B9: 25 (2009/2010) | D9: ANGOLA | E9: JAMBI | F9: INSTITUT TEKNOLOGI NASIONAL | H9: HUKUM / LEGAL / NOTARIS | I9: PENYEDIAAN BARANG DAN PELAYANAN | K9: MANUFAKTUR / PABRIK
B10: 26 (2010/2011) | D10: ANTIGUA DAN BARBUDA | E10: JAWA BARAT | F10: INSTITUT TEKNOLOGI SEPULUH NOPEMBER | H10: HRD / PERSONALIA / REKRUTMEN | I10: MANUFAKTUR DAN PRODUKSI | K10: RETAIL / PERDAGANGAN / FMCG
B11: 27 (2011/2012) | D11: ARAB SAUDI | E11: JAWA TENGAH | F11: POLITEKNIK ELEKTRONIKA NEGERI SURABAYA | H11: IT / SOFTWARE / DATA | I11: PERTANIAN DAN PETERNAKAN | K11: MEDIA / KREATIF / HIBURAN
B12: 28 (2012/2013) | D12: ARGENTINA | E12: JAWA TIMUR | F12: POLITEKNIK NEGERI BANDUNG | H12: JURNALIS / PENULIS / CONTENT | I12: KOMUNIKASI DAN MEDIA | K12: HUKUM / LEGAL
B13: 29 (2013/2014) | D13: ARMENIA | E13: KALIMANTAN BARAT | F13: POLITEKNIK NEGERI BATAM | H13: KONSULTAN / ANALIS | I13: KESEHATAN DAN KECANTIKAN | K13: PARIWISATA / HOTEL / F&B
B14: 30 (2014/2015) | D14: AUSTRALIA | E14: KALIMANTAN SELATAN | F14: POLITEKNIK NEGERI MALANG | H14: LOGISTIK / SUPPLY CHAIN / OPERASIONAL | I14: HIBURAN DAN REKREASI | K14: LOGISTIK / TRANSPORTASI
B15: 31 (2015/2016) | D15: AUSTRIA | E15: KALIMANTAN TENGAH | F15: POLITEKNIK NEGERI SAMARINDA | H15: MARKETING / SALES / PR | I15: TRANSPORTASI DAN LOGISTIK | K15: PERTANIAN / PERKEBUNAN
B16: 32 (2016/2017) | D16: AZERBAIJAN | E16: KALIMANTAN TIMUR | F16: POLITEKNIK NEGERI SEMARANG | H16: PELAYANAN PUBLIK / ASN / TNI / POLRI | I16: KEUANGAN DAN INVESTASI | K16: LSM / NON-PROFIT
... B18: 34 (2018/2019) | D18: BAHRAIN | E18: KEPULAUAN BANGKA BELITUNG | F18: SEKOLAH TINGGI ILMU EKONOMI YKPN | H18: MANAJEMEN / EKSEKUTIF (CEO/GM/MANAGER) | I18: LINGKUNGAN DAN ENERGI | K18: LAINNYA
B19: 35 (2019/2020) | D19: BANGLADESH | E19: KEPULAUAN RIAU | F19: STKIP ABDI WACANA WAMENA | H19: MAHASISWA / PELAJAR | I19: PERJALANAN DAN PARIWISATA
B20: 36 (2020/2021) | D20: BARBADOS | E20: LAMPUNG | F20: UNIVERSITAS AIRLANGGA | H20: LAINNYA | I20: HUKUM / JASA HUKUM
B21: 37 (2021/2022) | D21: BELANDA | E21: MALUKU | F21: UNIVERSITAS ANDALAS
B22: 38 (2022/2023) | D22: BELARUS | E22: MALUKU UTARA | F22: UNIVERSITAS ATMA JAYA YOGYAKARTA
B23: 39 (2023/2024) | D23: BELGIA | E23: NUSA TENGGARA BARAT | F23: UNIVERSITAS BANGKA BELITUNG
B24: 40 (2024/2025) | D24: BELIZE | E24: NUSA TENGGARA TIMUR | F24: UNIVERSITAS BENGKULU
D25: BENIN | E25: PAPUA | F25: UNIVERSITAS BINA NUSANTARA
D26: BHUTAN | E26: PAPUA BARAT | F26: UNIVERSITAS BORNEO TARAKAN
D27: BOLIVIA | E27: PAPUA BARAT DAYA | F27: UNIVERSITAS BRAWIJAYA
D28: BOSNIA DAN HERZEGOVINA | E28: PAPUA PEGUNUNGAN | F28: UNIVERSITAS CENDRAWASIH
D29: BOTSWANA | E29: PAPUA SELATAN | F29: UNIVERSITAS DIAN NUSWANTORO
D30: BRASIL | E30: PAPUA TENGAH | F30: UNIVERSITAS DIPONEGORO
D31: BRITANIA RAYA (INGGRIS) | E31: RIAU | F31: UNIVERSITAS HALU OLEO
D32: BRUNEI DARUSSALAM | E32: SULAWESI BARAT | F32: UNIVERSITAS ISLAM BANDUNG
D33: BULGARIA | E33: SULAWESI SELATAN | F33: UNIVERSITAS ISLAM MALANG
D34: BURKINA FASO | E34: SULAWESI TENGAH | F34: UNIVERSITAS ISLAM NEGERI SUNAN AMPEL
D35: BURUNDI | E35: SULAWESI TENGGARA | F35: UNIVERSITAS ISLAM NEGERI SUNAN GUNUNG DJATI
D36: CABO VERDE | E36: SULAWESI UTARA | F36: UNIVERSITAS ISLAM NEGERI SUNAN KALIJAGA
... D39: CHILI | E39: SUMATERA UTARA | F39: UNIVERSITAS JAMBI
D40: CHINA (TIONGKOK) | E40: =UPPER(Experiment!X40:X77) | F40: UNIVERSITAS JEMBER
D41: DENMARK | E41: =UPPER(Experiment!X41:X78) | F41: UNIVERSITAS JENDERAL ACHMAD YANI
D42: DJIBOUTI | E42: =UPPER(Experiment!X42:X79) | F42: UNIVERSITAS JENDERAL SOEDIRMAN
D43: DOMINIKA | E43: =UPPER(Experiment!X43:X80) | F43: UNIVERSITAS KATOLIK INDONESIA ATMA JAYA
...

Sheet Config
A1: Kolom A (Kunci) | B1: Kolom B (Nilai) | C1: Keterangan
A2: SHEET_NAME | B2: Database | C2: Nama Sheet Sumber Data Anggota
A3: DAILY_LIMIT | B3: 79 | C3: Batas maksimum email per hari
A4: DEFAULT_PIN | B4: 123123 | C4: PIN awal yang akan diinformasikan | D4: //FIX or Random seed?
A5: WEBSITE_LINK | B5: https://script.google.com/macros/s/AKfycbwFqxi5wvtTKNv37COGQWtr0WUrjmMICkMM5j1218s7Lk3FeU7HTCPR6Is1rL3cdcNA/exec | C5: Tautan website login
A6: NAMA_ORGANISASI | B6: Ikatan Alumni Djarum Beasiswa Plus | C6: Nama yang akan muncul di akhir email

Sheet Log_Pengiriman
A1: Waktu Pengiriman | B1: ID Anggota | C1: Email Tujuan | D1: Status | E1: Pesan Error/Keterangan
A2: 1/12/2025, 11.28.51 | B2: DBP00000000 | C2: halo.ikadbp@gmail.com | D2: TERKIRIM | E2: Berhasil dikirim.
A3: 1/12/2025, 11.30.44 | B3: DBP00000000 | C3: halo.ikadbp@gmail.com | D3: TERKIRIM | E3: Berhasil dikirim.
A4: 1/12/2025, 11.33.56 | B4: DBP00000000 | C4: halo.ikadbp@gmail.com | D4: TERKIRIM | E4: Berhasil dikirim.
A5: 17/12/2025, 17.57.37 | B5: DBP01000001 | C5: akbar.lawyer85@gmail.com | D5: TERKIRIM | E5: Berhasil dikirim.
A6: 17/12/2025, 17.57.38 | B6: DBP01000002 | C6: avgoenadi@gmail.com | D6: TERKIRIM | E6: Berhasil dikirim.
A7: 17/12/2025, 17.57.39 | B7: DBP01000003 | C7: gema.kusumaputri@gmail.com | D7: TERKIRIM | E7: Berhasil dikirim.
A8: 17/12/2025, 17.57.40 | B8: DBP01000004 | C8: putuagnia@gmail.com | D8: TERKIRIM | E8: Berhasil dikirim.
A9: 17/12/2025, 17.57.41 | B9: DBP01000005 | C9: dante.darmawangsa@upi.edu | D9: TERKIRIM | E9: Berhasil dikirim.
A10: 17/12/2025, 17.57.44 | B10: DBP01000006 | C10: ratri.mustikaning.h@gmail.com | D10: TERKIRIM | E10: Berhasil dikirim.
A11: 17/12/2025, 17.57.45 | B11: DBP01000007 | C11: puti.kemala.tanjung@gmail.com | D11: TERKIRIM | E11: Berhasil dikirim.
A12: 17/12/2025, 17.57.46 | B12: DBP01000008 | C12: roroajengtaufik@gmail.com | D12: TERKIRIM | E12: Berhasil dikirim.
... A21: 17/12/2025, 17.57.57 | B21: DBP01000017 | C21: nurrohmanazis1992@gmail.com | D21: TERKIRIM | E21: Berhasil dikirim.
A22: 17/12/2025, 17.57.58 | B22: DBP01000018 | D22: SKIP | E22: Email kosong atau format tidak valid.
A23: 17/12/2025, 17.57.58 | B23: DBP01000019 | C23: nicho.tarigan@gmail.com | D23: TERKIRIM | E23: Berhasil dikirim.
A24: 17/12/2025, 17.57.59 | B24: DBP01000020 | C24: Ogyfabrio@gmail.com | D24: TERKIRIM | E24: Berhasil dikirim.
A25: 17/12/2025, 17.58.00 | B25: DBP01000021 | C25: suhandies@gmail.com | D25: TERKIRIM | E25: Berhasil dikirim.
A26: 17/12/2025, 17.58.01 | B26: DBP01000022 | C26: riyadhi.atha@gmail.com | D26: TERKIRIM | E26: Berhasil dikirim.
A27: 17/12/2025, 17.58.04 | B27: DBP01000023 | C27: Marthanitaflorentinas@gmail.com | D27: TERKIRIM | E27: Berhasil dikirim.
A28: 17/12/2025, 17.58.05 | B28: DBP01000024 | C28: ferdinand.hiu@gmail.com | D28: TERKIRIM | E28: Berhasil dikirim.
A29: 17/12/2025, 17.58.06 | B29: DBP01000025 | C29: sagitas@xlfutureleaders.com | D29: TERKIRIM | E29: Berhasil dikirim.
A30: 17/12/2025, 17.58.07 | B30: DBP01000026 | C30: herozh94@gmail.com | D30: TERKIRIM | E30: Berhasil dikirim.
A31: 17/12/2025, 17.58.08 | B31: DBP01000027 | C31: Fjrhdy11@gmail.com | D31: TERKIRIM | E31: Berhasil dikirim.
A32: 17/12/2025, 17.58.09 | B32: DBP01000028 | C32: khasanm86@gmail.com | D32: TERKIRIM | E32: Berhasil dikirim.
A33: 17/12/2025, 17.58.10 | B33: DBP01000029 | C33: ilham.pbd@gmail.com | D33: TERKIRIM | E33: Berhasil dikirim.
A34: 17/12/2025, 17.58.11 | B34: DBP01000030 | C34: shafi.faris33@gmail.com | D34: TERKIRIM | E34: Berhasil dikirim.
... A39: 17/12/2025, 17.58.18 | B39: DBP01000035 | C39: yudith.tm@gmail.com | D39: TERKIRIM | E39: Berhasil dikirim.
A40: 17/12/2025, 17.58.20 | B40: DBP01000036 | D40: SKIP | E40: Email kosong atau format tidak valid.
A41: 17/12/2025, 17.58.20 | B41: DBP01000037 | C41: deidranataliet@gmail.com | D41: TERKIRIM | E41: Berhasil dikirim.
A42: 17/12/2025, 17.58.21 | B42: DBP01000038 | C42: dianboer@gmail.com | D42: TERKIRIM | E42: Berhasil dikirim.
A43: 17/12/2025, 17.58.22 | B43: DBP01000039 | C43: pelitawati1@gmail.com | D43: TERKIRIM | E43: Berhasil dikirim.
A44: 17/12/2025, 17.58.23 | B44: DBP01000040 | C44: ricohalim46@gmail.com | D44: TERKIRIM | E44: Berhasil dikirim.
A45: 17/12/2025, 17.58.24 | B45: DBP01000041 | C45: citra.asmara.83@gmail.com | D45: TERKIRIM | E45: Berhasil dikirim.
A46: 17/12/2025, 17.58.25 | B46: DBP01000042 | C46: cynthiakp.ckp@gmail.com | D46: TERKIRIM | E46: Berhasil dikirim.
A47: 17/12/2025, 17.58.26 | B47: DBP01000043 | C47: solehrifai@gmail.com | D47: TERKIRIM | E47: Berhasil dikirim.
A48: 17/12/2025, 17.58.29 | B48: DBP01000044 | C48: iqbalfa5@gmail.com | D48: TERKIRIM | E48: Berhasil dikirim.
A49: 17/12/2025, 17.58.30 | B49: DBP01000045 | C49: annisa.latu12@gmail.com | D49: TERKIRIM | E49: Berhasil dikirim.
A50: 17/12/2025, 17.58.31 | B50: DBP01000046 | C50: faizaldikky@gmail.com | D50: TERKIRIM | E50: Berhasil dikirim.
A51: 17/12/2025, 17.58.32 | B51: DBP01000047 | C51: veronicamdn9@gmail.com | D51: TERKIRIM | E51: Berhasil dikirim.
A52: 17/12/2025, 17.58.33 | B52: DBP01000048 | D52: SKIP | E52: Email kosong atau format tidak valid.
...

Sheet Experiment
A1: Jenis Pekerjaan | D1: Nama Instansi | L1: 18 | M1: 2002 | N1: 2003 | O1: =L1&" ("&M1&"/"&N1&")" -> 18 (2002/2003) | R1: No,Nama Negara,Benua | W1: No | X1: Nama Provinsi | Y1: Ibu Kota
A2: Profesional | D2: GURITNO and PARTNERS - Law Firm | H2: Laki-laki | I2: =UPPER(H2) -> LAKI-LAKI | L2: 19 | M2: 2003 | N2: 2004 | O2: =L2&" ("&M2&"/"&N2&")" -> 19 (2003/2004) | R2: 1,Afganistan,Asia | S2: =IFERROR(__xludf.DUMMYFUNCTION("SPLIT(R2,"","")"),1.0) -> 1 | T2: =IFERROR(__xludf.DUMMYFUNCTION("""COMPUTED_VALUE"""),"Afganistan") -> Afganistan | U2: =IFERROR(__xludf.DUMMYFUNCTION("""COMPUTED_VALUE"""),"Asia") -> Asia | W2: 1 | X2: Aceh | Y2: Banda Aceh | AA2: IAIN Kudus | AB2: =UPPER(AA2) -> IAIN KUDUS
A3: Pegawai Swasta | D3: PT. Parkland World Indonesia Jepara | H3: Laki-laki | I3: =UPPER(H3) -> LAKI-LAKI | L3: 20 | M3: 2004 | N3: 2005 | O3: =L3&" ("&M3&"/"&N3&")" -> 20 (2004/2005) | R3: 2,Afrika Selatan,Afrika | S3: =IFERROR(__xludf.DUMMYFUNCTION("SPLIT(R3,"","")"),2.0) -> 2 | T3: =IFERROR(__xludf.DUMMYFUNCTION("""COMPUTED_VALUE"""),"Afrika Selatan") -> Afrika Selatan | U3: =IFERROR(__xludf.DUMMYFUNCTION("""COMPUTED_VALUE"""),"Afrika") -> Afrika | W3: 2 | X3: Bali | Y3: Denpasar | AA3: Institut Kesenian Jakarta | AB3: =UPPER(AA3) -> INSTITUT KESENIAN JAKARTA
A4: Pegawai Swasta | D4: PT. Nutrifood | H4: Perempuan | I4: =UPPER(H4) -> PEREMPUAN | L4: 21 | M4: 2005 | N4: 2006 | O4: =L4&" ("&M4&"/"&N4&")" -> 21 (2005/2006) | R4: 3,Albania,Eropa | S4: =IFERROR(__xludf.DUMMYFUNCTION("SPLIT(R4,"","")"),3.0) -> 3 | T4: =IFERROR(__xludf.DUMMYFUNCTION("""COMPUTED_VALUE"""),"Albania") -> Albania | U4: =IFERROR(__xludf.DUMMYFUNCTION("""COMPUTED_VALUE"""),"Eropa") -> Eropa | W4: 3 | X4: Banten | Y4: Serang | AA4: Institut Pertanian Bogor | AB4: =UPPER(AA4) -> INSTITUT PERTANIAN BOGOR
A5: Pegawai Swasta | D5: PT. PRIMA AGRO TECH | H5: Perempuan | I5: =UPPER(H5) -> PEREMPUAN | L5: 22 | M5: 2006 | N5: 2007 | O5: =L5&" ("&M5&"/"&N5&")" -> 22 (2006/2007) | R5: 4,Aljazair,Afrika | S5: =IFERROR(__xludf.DUMMYFUNCTION("SPLIT(R5,"","")"),4.0) -> 4 | T5: =IFERROR(__xludf.DUMMYFUNCTION("""COMPUTED_VALUE"""),"Aljazair") -> Aljazair | U5: =IFERROR(__xludf.DUMMYFUNCTION("""COMPUTED_VALUE"""),"Afrika") -> Afrika | W5: 4 | X5: Bengkulu | Y5: Bengkulu | AA5: Institut Seni Indonesia Yogyakarta | AB5: =UPPER(AA5) -> INSTITUT SENI INDONESIA YOGYAKARTA
A6: BUMN/Pemerintahan(PNS) | D6: PT. Bank Negara Indonesia (Persero), Tbk | H6: Laki-laki | I6: =UPPER(H6) -> LAKI-LAKI | L6: 23 | M6: 2007 | N6: 2008 | O6: =L6&" ("&M6&"/"&N6&")" -> 23 (2007/2008) | R6: 5,Amerika Serikat,Amerika Utara | S6: =IFERROR(__xludf.DUMMYFUNCTION("SPLIT(R6,"","")"),5.0) -> 5 | T6: =IFERROR(__xludf.DUMMYFUNCTION("""COMPUTED_VALUE"""),"Amerika Serikat") -> Amerika Serikat | U6: =IFERROR(__xludf.DUMMYFUNCTION("""COMPUTED_VALUE"""),"Amerika Utara") -> Amerika Utara | W6: 5 | X6: DI Yogyakarta | Y6: Yogyakarta | AA6: Institut Teknologi Bandung | AB6: =UPPER(AA6) -> INSTITUT TEKNOLOGI BANDUNG
A7: Wiraswasta | D7: Companera Business & Companera Apparel | H7: Perempuan | I7: =UPPER(H7) -> PEREMPUAN | L7: 24 | M7: 2008 | N7: 2009 | O7: =L7&" ("&M7&"/"&N7&")" -> 24 (2008/2009) | R7: 6,Andorra,Eropa | S7: =IFERROR(__xludf.DUMMYFUNCTION("SPLIT(R7,"","")"),6.0) -> 6 | T7: =IFERROR(__xludf.DUMMYFUNCTION("""COMPUTED_VALUE"""),"Andorra") -> Andorra | U7: =IFERROR(__xludf.DUMMYFUNCTION("""COMPUTED_VALUE"""),"Eropa") -> Eropa | W7: 6 | X7: DKI Jakarta | Y7: Jakarta | AA7: Institut Teknologi Harapan Bangsa | AB7: =UPPER(AA7) -> INSTITUT TEKNOLOGI HARAPAN BANGSA
A8: Pegawai Swasta | D8: PT. Home center indonesia (kawan lama group) | H8: Perempuan | I8: =UPPER(H8) -> PEREMPUAN | L8: 25 | M8: 2009 | N8: 2010 | O8: =L8&" ("&M8&"/"&N8&")" -> 25 (2009/2010) | R8: 7,Angola,Afrika | S8: =IFERROR(__xludf.DUMMYFUNCTION("SPLIT(R8,"","")"),7.0) -> 7 | T8: =IFERROR(__xludf.DUMMYFUNCTION("""COMPUTED_VALUE"""),"Angola") -> Angola | U8: =IFERROR(__xludf.DUMMYFUNCTION("""COMPUTED_VALUE"""),"Afrika") -> Afrika | W8: 7 | X8: Gorontalo | Y8: Gorontalo | AA8: Institut Teknologi Kalimantan | AB8: =UPPER(AA8) -> INSTITUT TEKNOLOGI KALIMANTAN
A9: Belum Bekerja | D9: Belum Bekerja | H9: Perempuan | I9: =UPPER(H9) -> PEREMPUAN | L9: 26 | M9: 2010 | N9: 2011 | O9: =L9&" ("&M9&"/"&N9&")" -> 26 (2010/2011) | R9: 8,Antigua dan Barbuda,Amerika Utara | S9: =IFERROR(__xludf.DUMMYFUNCTION("SPLIT(R9,"","")"),8.0) -> 8 | T9: =IFERROR(__xludf.DUMMYFUNCTION("""COMPUTED_VALUE"""),"Antigua dan Barbuda") -> Antigua dan Barbuda | U9: =IFERROR(__xludf.DUMMYFUNCTION("""COMPUTED_VALUE"""),"Amerika Utara") -> Amerika Utara | W9: 8 | X9: Jambi | Y9: Jambi | AA9: Institut Teknologi Nasional | AB9: =UPPER(AA9) -> INSTITUT TEKNOLOGI NASIONAL
A10: Pegawai Swasta | D10: Astra International - Toyota Auto2000 | H10: Laki-laki | I10: =UPPER(H10) -> LAKI-LAKI | L10: 27 | M10: 2011 | N10: 2012 | O10: =L10&" ("&M10&"/"&N10&")" -> 27 (2011/2012) | R10: 9,Arab Saudi,Asia | S10: =IFERROR(__xludf.DUMMYFUNCTION("SPLIT(R10,"","")"),9.0) -> 9 | T10: =IFERROR(__xludf.DUMMYFUNCTION("""COMPUTED_VALUE"""),"Arab Saudi") -> Arab Saudi | U10: =IFERROR(__xludf.DUMMYFUNCTION("""COMPUTED_VALUE"""),"Asia") -> Asia | W10: 9 | X10: Jawa Barat | Y10: Bandung | AA10: Institut Teknologi Sepuluh Nopember | AB10: =UPPER(AA10) -> INSTITUT TEKNOLOGI SEPULUH NOPEMBER
A11: BUMN/Pemerintahan(PNS) | D11: PT PLN INDONESIA POWER | H11: Laki-laki | I11: =UPPER(H11) -> LAKI-LAKI | L11: 28 | M11: 2012 | N11: 2013 | O11: =L11&" ("&M11&"/"&N11&")" -> 28 (2012/2013) | R11: 10,Argentina,Amerika Selatan | S11: =IFERROR(__xludf.DUMMYFUNCTION("SPLIT(R11,"","")"),10.0) -> 10 | T11: =IFERROR(__xludf.DUMMYFUNCTION("""COMPUTED_VALUE"""),"Argentina") -> Argentina | U11: =IFERROR(__xludf.DUMMYFUNCTION("""COMPUTED_VALUE"""),"Amerika Selatan") -> Amerika Selatan | W11: 10 | X11: Jawa Tengah | Y11: Semarang | AA11: Politeknik Elektronika Negeri Surabaya | AB11: =UPPER(AA11) -> POLITEKNIK ELEKTRONIKA NEGERI SURABAYA
A12: Pegawai Swasta | D12: MarkPlus | H12: Laki-laki | I12: =UPPER(H12) -> LAKI-LAKI | L12: 29 | M12: 2013 | N12: 2014 | O12: =L12&" ("&M12&"/"&N12&")" -> 29 (2013/2014) | R12: 11,Armenia,Asia | S12: =IFERROR(__xludf.DUMMYFUNCTION("SPLIT(R12,"","")"),11.0) -> 11 | T12: =IFERROR(__xludf.DUMMYFUNCTION("""COMPUTED_VALUE"""),"Armenia") -> Armenia | U12: =IFERROR(__xludf.DUMMYFUNCTION("""COMPUTED_VALUE"""),"Asia") -> Asia | W12: 11 | X12: Jawa Timur | Y12: Surabaya | AA12: Politeknik Negeri Bandung | AB12: =UPPER(AA12) -> POLITEKNIK NEGERI BANDUNG
A13: Mahasiswa | D13: Belum Bekerja | H13: Laki-laki | I13: =UPPER(H13) -> LAKI-LAKI | L13: 30 | M13: 2014 | N13: 2015 | O13: =L13&" ("&M13&"/"&N13&")" -> 30 (2014/2015) | R13: 12,Australia,Australia/Oceania | S13: =IFERROR(__xludf.DUMMYFUNCTION("SPLIT(R13,"","")"),12.0) -> 12 | T13: =IFERROR(__xludf.DUMMYFUNCTION("""COMPUTED_VALUE"""),"Australia") -> Australia | U13: =IFERROR(__xludf.DUMMYFUNCTION("""COMPUTED_VALUE"""),"Australia/Oceania") -> Australia/Oceania | W13: 12 | X13: Kalimantan Barat | Y13: Pontianak | AA13: Politeknik Negeri Batam | AB13: =UPPER(AA13) -> POLITEKNIK NEGERI BATAM
A14: Pegawai Swasta | D14: Yayasan Rumah Energi | H14: Perempuan | I14: =UPPER(H14) -> PEREMPUAN | L14: 31 | M14: 2015 | N14: 2016 | O14: =L14&" ("&M14&"/"&N14&")" -> 31 (2015/2016) | R14: 13,Austria,Eropa | S14: =IFERROR(__xludf.DUMMYFUNCTION("SPLIT(R14,"","")"),13.0) -> 13 | T14: =IFERROR(__xludf.DUMMYFUNCTION("""COMPUTED_VALUE"""),"Austria") -> Austria | U14: =IFERROR(__xludf.DUMMYFUNCTION("""COMPUTED_VALUE"""),"Eropa") -> Eropa | W14: 13 | X14: Kalimantan Selatan | Y14: Banjarbaru | AA14: Politeknik Negeri Malang | AB14: =UPPER(AA14) -> POLITEKNIK NEGERI MALANG
A15: Pegawai Swasta | D15: PT YUKBISNIS INDONESIA | H15: Laki-laki | I15: =UPPER(H15) -> LAKI-LAKI | L15: 32 | M15: 2016 | N15: 2017 | O15: =L15&" ("&M15&"/"&N15&")" -> 32 (2016/2017) | R15: 14,Azerbaijan,Asia | S15: =IFERROR(__xludf.DUMMYFUNCTION("SPLIT(R15,"","")"),14.0) -> 14 | T15: =IFERROR(__xludf.DUMMYFUNCTION("""COMPUTED_VALUE"""),"Azerbaijan") -> Azerbaijan | U15: =IFERROR(__xludf.DUMMYFUNCTION("""COMPUTED_VALUE"""),"Asia") -> Asia | W15: 14 | X15: Kalimantan Tengah | Y15: Palangka Raya | AA15: Politeknik Negeri Samarinda | AB15: =UPPER(AA15) -> POLITEKNIK NEGERI SAMARINDA
A16: Pegawai Swasta | D16: PT.Grab Teknologi Indonesia | H16: Perempuan | I16: =UPPER(H16) -> PEREMPUAN | L16: 33 | M16: 2017 | N16: 2018 | O16: =L16&" ("&M16&"/"&N16&")" -> 33 (2017/2018) | R16: 15,Bahama,Amerika Utara | S16: =IFERROR(__xludf.DUMMYFUNCTION("SPLIT(R16,"","")"),15.0) -> 15 | T16: =IFERROR(__xludf.DUMMYFUNCTION("""COMPUTED_VALUE"""),"Bahama") -> Bahama | U16: =IFERROR(__xludf.DUMMYFUNCTION("""COMPUTED_VALUE"""),"Amerika Utara") -> Amerika Utara | W16: 15 | X16: Kalimantan Timur | Y16: Samarinda | AA16: Politeknik Negeri Semarang | AB16: =UPPER(AA16) -> POLITEKNIK NEGERI SEMARANG
A17: BUMN/Pemerintahan(PNS) | D17: Bank Mandiri | H17: Laki-laki | I17: =UPPER(H17) -> LAKI-LAKI | L17: 34 | M17: 2018 | N17: 2019 | O17: =L17&" ("&M17&"/"&N17&")" -> 34 (2018/2019) | R17: 16,Bahrain,Asia | S17: =IFERROR(__xludf.DUMMYFUNCTION("SPLIT(R17,"","")"),16.0) -> 16 | T17: =IFERROR(__xludf.DUMMYFUNCTION("""COMPUTED_VALUE"""),"Bahrain") -> Bahrain | U17: =IFERROR(__xludf.DUMMYFUNCTION("""COMPUTED_VALUE"""),"Asia") -> Asia | W17: 16 | X17: Kalimantan Utara | Y17: Tanjung Selor | AA17: Sekolah Tinggi Ilmu Ekonomi Malangkucecwara | AB17: =UPPER(AA17) -> SEKOLAH TINGGI ILMU EKONOMI MALANGKUCECWARA
A18: BUMN/Pemerintahan(PNS) | D18: PT. Bank Mandiri (Persero) Tbk | H18: Laki-laki | I18: =UPPER(H18) -> LAKI-LAKI | L18: 35 | M18: 2019 | N18: 2020 | O18: =L18&" ("&M18&"/"&N18&")" -> 35 (2019/2020) | R18: 17,Bangladesh,Asia | S18: =IFERROR(__xludf.DUMMYFUNCTION("SPLIT(R18,"","")"),17.0) -> 17 | T18: =IFERROR(__xludf.DUMMYFUNCTION("""COMPUTED_VALUE"""),"Bangladesh") -> Bangladesh | U18: =IFERROR(__xludf.DUMMYFUNCTION("""COMPUTED_VALUE"""),"Asia") -> Asia | W18: 17 | X18: Kepulauan Bangka Belitung | Y18: Pangkal Pinang | AA18: Sekolah Tinggi Ilmu Ekonomi YKPN | AB18: =UPPER(AA18) -> SEKOLAH TINGGI ILMU EKONOMI YKPN
A19: Dosen | D19: Institut Seni Budaya Indonesia Aceh | H19: Laki-laki | I19: =UPPER(H19) -> LAKI-LAKI | L19: 36 | M19: 2020 | N19: 2021 | O19: =L19&" ("&M19&"/"&N19&")" -> 36 (2020/2021) | R19: 18,Barbados,Amerika Utara | S19: =IFERROR(__xludf.DUMMYFUNCTION("SPLIT(R19,"","")"),18.0) -> 18 | T19: =IFERROR(__xludf.DUMMYFUNCTION("""COMPUTED_VALUE"""),"Barbados") -> Barbados | U19: =IFERROR(__xludf.DUMMYFUNCTION("""COMPUTED_VALUE"""),"Amerika Utara") -> Amerika Utara | W19: 18 | X19: Kepulauan Riau | Y19: Tanjung Pinang | AA19: STKIP Abdi Wacana Wamena | AB19: =UPPER(AA19) -> STKIP ABDI WACANA WAMENA
A20: Pegawai Swasta | D20: PT. Fortius Solusi Informatika | H20: Laki-laki | I20: =UPPER(H20) -> LAKI-LAKI | L20: 37 | M20: 2021 | N20: 2022 | O20: =L20&" ("&M20&"/"&N20&")" -> 37 (2021/2022) | R20: 19,Belanda,Eropa | S20: =IFERROR(__xludf.DUMMYFUNCTION("SPLIT(R20,"","")"),19.0) -> 19 | T20: =IFERROR(__xludf.DUMMYFUNCTION("""COMPUTED_VALUE"""),"Belanda") -> Belanda | U20: =IFERROR(__xludf.DUMMYFUNCTION("""COMPUTED_VALUE"""),"Eropa") -> Eropa | W20: 19 | X20: Lampung | Y20: Bandar Lampung | AA20: Universitas Airlangga | AB20: =UPPER(AA20) -> UNIVERSITAS AIRLANGGA
A21: Coding Tutor | D21: Algorithmics Indonesia dan Timedoor Academy | H21: Laki-laki | I21: =UPPER(H21) -> LAKI-LAKI | L21: 38 | M21: 2022 | N21: 2023 | O21: =L21&" ("&M21&"/"&N21&")" -> 38 (2022/2023) | R21: 20,Belarus,Eropa | S21: =IFERROR(__xludf.DUMMYFUNCTION("SPLIT(R21,"","")"),20.0) -> 20 | T21: =IFERROR(__xludf.DUMMYFUNCTION("""COMPUTED_VALUE"""),"Belarus") -> Belarus | U21: =IFERROR(__xludf.DUMMYFUNCTION("""COMPUTED_VALUE"""),"Eropa") -> Eropa | W21: 20 | X21: Maluku | Y21: Ambon | AA21: Universitas Andalas | AB21: =UPPER(AA21) -> UNIVERSITAS ANDALAS
A22: Pegawai Swasta | D22: KAP Parker Russell Indonesia | H22: Laki-laki | I22: =UPPER(H22) -> LAKI-LAKI | L22: 39 | M22: 2023 | N22: 2024 | O22: =L22&" ("&M22&"/"&N22&")" -> 39 (2023/2024) | R22: 21,Belgia,Eropa | S22: =IFERROR(__xludf.DUMMYFUNCTION("SPLIT(R22,"","")"),21.0) -> 21 | T22: =IFERROR(__xludf.DUMMYFUNCTION("""COMPUTED_VALUE"""),"Belgia") -> Belgia | U22: =IFERROR(__xludf.DUMMYFUNCTION("""COMPUTED_VALUE"""),"Eropa") -> Eropa | W22: 21 | X22: Maluku Utara | Y22: Sofifi | AA22: Universitas Atma Jaya Yogyakarta | AB22: =UPPER(AA22) -> UNIVERSITAS ATMA JAYA YOGYAKARTA
A23: Pegawai Swasta | D23: PT. Indonesia Epson Industry | H23: Perempuan | I23: =UPPER(H23) -> PEREMPUAN | L23: 40 | M23: 2024 | N23: 2025 | O23: =L23&" ("&M23&"/"&N23&")" -> 40 (2024/2025) | R23: 22,Belize,Amerika Utara | S23: =IFERROR(__xludf.DUMMYFUNCTION("SPLIT(R23,"","")"),22.0) -> 22 | T23: =IFERROR(__xludf.DUMMYFUNCTION("""COMPUTED_VALUE"""),"Belize") -> Belize | U23: =IFERROR(__xludf.DUMMYFUNCTION("""COMPUTED_VALUE"""),"Amerika Utara") -> Amerika Utara | W23: 22 | X23: Nusa Tenggara Barat | Y23: Mataram | AA23: Universitas Bangka Belitung | AB23: =UPPER(AA23) -> UNIVERSITAS BANGKA BELITUNG
A24: Mahasiswa | D24: Universitas Muria Kudus | H24: Laki-laki | I24: =UPPER(H24) -> LAKI-LAKI | R24: 23,Benin,Afrika | S24: =IFERROR(__xludf.DUMMYFUNCTION("SPLIT(R24,"","")"),23.0) -> 23 | T24: =IFERROR(__xludf.DUMMYFUNCTION("""COMPUTED_VALUE"""),"Benin") -> Benin | U24: =IFERROR(__xludf.DUMMYFUNCTION("""COMPUTED_VALUE"""),"Afrika") -> Afrika | W24: 23 | X24: Nusa Tenggara Timur | Y24: Kupang | AA24: Universitas Bengkulu | AB24: =UPPER(AA24) -> UNIVERSITAS BENGKULU
A25: Belum Bekerja | D25: Belum Bekerja | H25: Perempuan | I25: =UPPER(H25) -> PEREMPUAN | R25: 24,Bhutan,Asia | S25: =IFERROR(__xludf.DUMMYFUNCTION("SPLIT(R25,"","")"),24.0) -> 24 | T25: =IFERROR(__xludf.DUMMYFUNCTION("""COMPUTED_VALUE"""),"Bhutan") -> Bhutan | U25: =IFERROR(__xludf.DUMMYFUNCTION("""COMPUTED_VALUE"""),"Asia") -> Asia | W25: 24 | X25: Papua | Y25: Jayapura | AA25: Universitas Bina Nusantara | AB25: =UPPER(AA25) -> UNIVERSITAS BINA NUSANTARA
A26: Guru PPPK | D26: SMP Negeri 1 Pageruyung | H26: Laki-laki | I26: =UPPER(H26) -> LAKI-LAKI | R26: 25,Bolivia,Amerika Selatan | S26: =IFERROR(__xludf.DUMMYFUNCTION("SPLIT(R26,"","")"),25.0) -> 25 | T26: =IFERROR(__xludf.DUMMYFUNCTION("""COMPUTED_VALUE"""),"Bolivia") -> Bolivia | U26: =IFERROR(__xludf.DUMMYFUNCTION("""COMPUTED_VALUE"""),"Amerika Selatan") -> Amerika Selatan | W26: 25 | X26: Papua Barat | Y26: Manokwari | AA26: Universitas Borneo Tarakan | AB26: =UPPER(AA26) -> UNIVERSITAS BORNEO TARAKAN
A27: Pegawai Swasta | D27: PT Datacomm Diangraha | H27: Laki-laki | I27: =UPPER(H27) -> LAKI-LAKI | R27: 26,Bosnia dan Herzegovina,Eropa | S27: =IFERROR(__xludf.DUMMYFUNCTION("SPLIT(R27,"","")"),26.0) -> 26 | T27: =IFERROR(__xludf.DUMMYFUNCTION("""COMPUTED_VALUE"""),"Bosnia dan Herzegovina") -> Bosnia dan Herzegovina | U27: =IFERROR(__xludf.DUMMYFUNCTION("""COMPUTED_VALUE"""),"Eropa") -> Eropa | W27: 26 | X27: Papua Barat Daya | Y27: Sorong | AA27: Universitas Brawijaya | AB27: =UPPER(AA27) -> UNIVERSITAS BRAWIJAYA
A28: Pegawai Swasta | D28: BCA Finance | H28: Laki-laki | I28: =UPPER(H28) -> LAKI-LAKI | R28: 27,Botswana,Afrika | S28: =IFERROR(__xludf.DUMMYFUNCTION("SPLIT(R28,"","")"),27.0) -> 27 | T28: =IFERROR(__xludf.DUMMYFUNCTION("""COMPUTED_VALUE"""),"Botswana") -> Botswana | U28: =IFERROR(__xludf.DUMMYFUNCTION("""COMPUTED_VALUE"""),"Afrika") -> Afrika | W28: 27 | X28: Papua Pegunungan | Y28: Wamena | AA28: Universitas Cendrawasih | AB28: =UPPER(AA28) -> UNIVERSITAS CENDRAWASIH
A29: Wiraswasta | D29: PT Zurich Topas Life | H29: Laki-laki | I29: =UPPER(H29) -> LAKI-LAKI | R29: 28,Brasil,Amerika Selatan | S29: =IFERROR(__xludf.DUMMYFUNCTION("SPLIT(R29,"","")"),28.0) -> 28 | T29: =IFERROR(__xludf.DUMMYFUNCTION("""COMPUTED_VALUE"""),"Brasil") -> Brasil | U29: =IFERROR(__xludf.DUMMYFUNCTION("""COMPUTED_VALUE"""),"Amerika Selatan") -> Amerika Selatan | W29: 28 | X29: Papua Selatan | Y29: Merauke | AA29: Universitas Dian Nuswantoro | AB29: =UPPER(AA29) -> UNIVERSITAS DIAN NUSWANTORO
A30: Freelance | D30: Hotel 1O1 Urban Jakarta Thamrin | H30: Laki-laki | I30: =UPPER(H30) -> LAKI-LAKI | R30: 29,Britania Raya (Inggris),Eropa | S30: =IFERROR(__xludf.DUMMYFUNCTION("SPLIT(R30,"","")"),29.0) -> 29 | T30: =IFERROR(__xludf.DUMMYFUNCTION("""COMPUTED_VALUE"""),"Britania Raya (Inggris)") -> Britania Raya (Inggris) | U30: =IFERROR(__xludf.DUMMYFUNCTION("""COMPUTED_VALUE"""),"Eropa") -> Eropa | W30: 29 | X30: Papua Tengah | Y30: Nabire | AA30: Universitas Diponegoro | AB30: =UPPER(AA30) -> UNIVERSITAS DIPONEGORO
A31: Pegawai Swasta | D31: Motasa Indonesia | H31: Perempuan | I31: =UPPER(H31) -> PEREMPUAN | R31: 30,Brunei Darussalam,Asia | S31: =IFERROR(__xludf.DUMMYFUNCTION("SPLIT(R31,"","")"),30.0) -> 30 | T31: =IFERROR(__xludf.DUMMYFUNCTION("""COMPUTED_VALUE"""),"Brunei Darussalam") -> Brunei Darussalam | U31: =IFERROR(__xludf.DUMMYFUNCTION("""COMPUTED_VALUE"""),"Asia") -> Asia | W31: 30 | X31: Riau | Y31: Pekanbaru | AA31: Universitas Halu Oleo | AB31: =UPPER(AA31) -> UNIVERSITAS HALU OLEO
A32: Pegawai Swasta | D32: PT Geotronix Pratama Indonesia | H32: Perempuan | I32: =UPPER(H32) -> PEREMPUAN | R32: 31,Bulgaria,Eropa | S32: =IFERROR(__xludf.DUMMYFUNCTION("SPLIT(R32,"","")"),31.0) -> 31 | T32: =IFERROR(__xludf.DUMMYFUNCTION("""COMPUTED_VALUE"""),"Bulgaria") -> Bulgaria | U32: =IFERROR(__xludf.DUMMYFUNCTION("""COMPUTED_VALUE"""),"Eropa") -> Eropa | W32: 31 | X32: Sulawesi Barat | Y32: Mamuju | AA32: Universitas Islam Bandung | AB32: =UPPER(AA32) -> UNIVERSITAS ISLAM BANDUNG
A33: Pegawai Swasta | D33: PT Adlink Sinemedia Indonesia | H33: Perempuan | I33: =UPPER(H33) -> PEREMPUAN | R33: 32,Burkina Faso,Afrika | S33: =IFERROR(__xludf.DUMMYFUNCTION("SPLIT(R33,"","")"),32.0) -> 32 | T33: =IFERROR(__xludf.DUMMYFUNCTION("""COMPUTED_VALUE"""),"Burkina Faso") -> Burkina Faso | U33: =IFERROR(__xludf.DUMMYFUNCTION("""COMPUTED_VALUE"""),"Afrika") -> Afrika | W33: 32 | X33: Sulawesi Selatan | Y33: Makassar | AA33: Universitas Islam Malang | AB33: =UPPER(AA33) -> UNIVERSITAS ISLAM MALANG
A34: BUMN/Pemerintahan(PNS) | D34: PT. Bank Rakyat Indonesia Tbk. | H34: Perempuan | I34: =UPPER(H34) -> PEREMPUAN | R34: 33,Burundi,Afrika | S34: =IFERROR(__xludf.DUMMYFUNCTION("SPLIT(R34,"","")"),33.0) -> 33 | T34: =IFERROR(__xludf.DUMMYFUNCTION("""COMPUTED_VALUE"""),"Burundi") -> Burundi | U34: =IFERROR(__xludf.DUMMYFUNCTION("""COMPUTED_VALUE"""),"Afrika") -> Afrika | W34: 33 | X34: Sulawesi Tengah | Y34: Palu | AA34: Universitas Islam Negeri Sunan Ampel | AB34: =UPPER(AA34) -> UNIVERSITAS ISLAM NEGERI SUNAN AMPEL
A35: Dosen | D35: Universitas Mulawarman | H35: Perempuan | I35: =UPPER(H35) -> PEREMPUAN | R35: 34,Cabo Verde,Afrika | S35: =IFERROR(__xludf.DUMMYFUNCTION("SPLIT(R35,"","")"),34.0) -> 34 | T35: =IFERROR(__xludf.DUMMYFUNCTION("""COMPUTED_VALUE"""),"Cabo Verde") -> Cabo Verde | U35: =IFERROR(__xludf.DUMMYFUNCTION("""COMPUTED_VALUE"""),"Afrika") -> Afrika | W35: 34 | X35: Sulawesi Tenggara | Y35: Kendari | AA35: Universitas Islam Negeri Sunan Gunung Djati | AB35: =UPPER(AA35) -> UNIVERSITAS ISLAM NEGERI SUNAN GUNUNG DJATI
A36: Pegawai Swasta | D36: Ubiklan | H36: Laki-laki | I36: =UPPER(H36) -> LAKI-LAKI | R36: 35,Ceko (Republik Ceko),Eropa | S36: =IFERROR(__xludf.DUMMYFUNCTION("SPLIT(R36,"","")"),35.0) -> 35 | T36: =IFERROR(__xludf.DUMMYFUNCTION("""COMPUTED_VALUE"""),"Ceko (Republik Ceko)") -> Ceko (Republik Ceko) | U36: =IFERROR(__xludf.DUMMYFUNCTION("""COMPUTED_VALUE"""),"Eropa") -> Eropa | W36: 35 | X36: Sulawesi Utara | Y36: Manado | AA36: Universitas Islam Negeri Sunan Kalijaga | AB36: =UPPER(AA36) -> UNIVERSITAS ISLAM NEGERI SUNAN KALIJAGA
A37: Belum Bekerja | D37: Belum Bekerja | H37: Perempuan | I37: =UPPER(H37) -> PEREMPUAN | R37: 36,Chad,Afrika | S37: =IFERROR(__xludf.DUMMYFUNCTION("SPLIT(R37,"","")"),36.0) -> 36 | T37: =IFERROR(__xludf.DUMMYFUNCTION("""COMPUTED_VALUE"""),"Chad") -> Chad | U37: =IFERROR(__xludf.DUMMYFUNCTION("""COMPUTED_VALUE"""),"Afrika") -> Afrika | W37: 36 | X37: Sumatera Barat | Y37: Padang | AA37: Universitas Islam Negeri Syarif Hidayatullah | AB37: =UPPER(AA37) -> UNIVERSITAS ISLAM NEGERI SYARIF HIDAYATULLAH
A38: Pegawai Swasta | D38: PT Bumibaru | H38: Laki-laki | I38: =UPPER(H38) -> LAKI-LAKI | R38: 37,Chili,Amerika Selatan | S38: =IFERROR(__xludf.DUMMYFUNCTION("SPLIT(R38,"","")"),37.0) -> 37 | T38: =IFERROR(__xludf.DUMMYFUNCTION("""COMPUTED_VALUE"""),"Chili") -> Chili | U38: =IFERROR(__xludf.DUMMYFUNCTION("""COMPUTED_VALUE"""),"Amerika Selatan") -> Amerika Selatan | W38: 37 | X38: Sumatera Selatan | Y38: Palembang | AA38: Universitas Islam Negeri Walisongo | AB38: =UPPER(AA38) -> UNIVERSITAS ISLAM NEGERI WALISONGO
A39: Pegawai Swasta | D39: McKinsey and Company | H39: Perempuan | I39: =UPPER(H39) -> PEREMPUAN | R39: 38,China (Tiongkok),Asia | S39: =IFERROR(__xludf.DUMMYFUNCTION("SPLIT(R39,"","")"),38.0) -> 38 | T39: =IFERROR(__xludf.DUMMYFUNCTION("""COMPUTED_VALUE"""),"China (Tiongkok)") -> China (Tiongkok) | U39: =IFERROR(__xludf.DUMMYFUNCTION("""COMPUTED_VALUE"""),"Asia") -> Asia | W39: 38 | X39: Sumatera Utara | Y39: Medan | AA39: Universitas Jambi | AB39: =UPPER(AA39) -> UNIVERSITAS JAMBI
A40: BUMN/Pemerintahan(PNS) | D40: Kementerian Hukum dan HAM | H40: Perempuan | I40: =UPPER(H40) -> PEREMPUAN | R40: 39,Denmark,Eropa | S40: =IFERROR(__xludf.DUMMYFUNCTION("SPLIT(R40,"","")"),39.0) -> 39 | T40: =IFERROR(__xludf.DUMMYFUNCTION("""COMPUTED_VALUE"""),"Denmark") -> Denmark | U40: =IFERROR(__xludf.DUMMYFUNCTION("""COMPUTED_VALUE"""),"Eropa") -> Eropa | AA40: Universitas Jember | AB40: =UPPER(AA40) -> UNIVERSITAS JEMBER
...
